Workbook

Sheet Dashboard
B2: FEC Corporate Deals and Aggregators: Weekly Management Review
B3: E3 Events and Entertainments | Prepared by Rajan Pathak, Head of Operations (FEC & IT) | Tuesday management meeting
B4: Reporting week (ISO) | C4: 2026-W37 | D4: Previous week | E4: =IF(VALUE(RIGHT(C4,2))=1,LEFT(C4,4)-1&"-W52",LEFT(C4,6)&TEXT(VALUE(RIGHT(C4,2))-1,"00")) -> 2026-W36 | H4: Meeting date | J4: Reviewed by | K4: Mr. Adil
B5: Type the ISO week into C4 after pasting the new export into Weekly Log. Everything below recalculates. | C5: =E4 -> 2026-W36
B7: Partner redemptions | D7: Tickets under deals | F7: Discount given (QAR) | H7: Active partners | J7: Aggregator share of discount
B8: =Summary!B9 -> 194 | D8: =Summary!C9 -> 576 | F8: =Summary!D9 -> 12750.5 | H8: =Summary!E9&" of 21" -> 12 of 21 | J8: =IF(K16=0,0,K15/K16) -> 0.67981648
B10: =IF(COUNTIF('Weekly Log'!$G$5:$G$636,$E$4)=0,"No previous week in log yet",IF(Summary!B9-SUMPRODUCT(Summary!K25:K45)>=0,"+","")&TEXT(Summary!B9-SUMPRODUCT(Summary!K25:K45),"#,##0")&" vs previous week") -> No previous week in log yet
B12: Top partners this week | H12: Corporate discounts vs aggregator BOGO, this week
B13: Partner | C13: This week | D13: Prev week | E13: Change | F13: Month to date | H13: Category | I13: Redemptions | J13: Tickets | K13: Discount QAR | L13: QAR per redempt.
B14: =IFERROR(INDEX(Summary!$A$25:$A$45,MATCH(LARGE(Summary!$M$25:$M$45,1),Summary!$M$25:$M$45,0)),"") -> Imtyazat | C14: =IFERROR(INDEX(Summary!$C$25:$C$45,MATCH($B14,Summary!$A$25:$A$45,0)),0) -> 40 | D14: =IFERROR(INDEX(Summary!$K$25:$K$45,MATCH($B14,Summary!$A$25:$A$45,0)),0) -> 0 | E14: =C14-D14 -> 40 | F14: =IFERROR(INDEX(Summary!$D$25:$D$45,MATCH($B14,Summary!$A$25:$A$45,0)),0) -> 72 | H14: Corporate discount | I14: =SUMPRODUCT((Summary!$B$25:$B$45="Corporate discount")*Summary!$C$25:$C$45) -> 139 | J14: =SUMIFS('Weekly Log'!$J$5:$J$636,'Weekly Log'!$G$5:$G$636,$C$4,'Weekly Log'!$M$5:$M$636,"Corporate discount") -> 521 | K14: =SUMIFS('Weekly Log'!$K$5:$K$636,'Weekly Log'!$G$5:$G$636,$C$4,'Weekly Log'!$M$5:$M$636,"Corporate discount") -> 4082.5 | L14: =IF(I14=0,0,K14/I14) -> 29.370504
B15: =IFERROR(INDEX(Summary!$A$25:$A$45,MATCH(LARGE(Summary!$M$25:$M$45,2),Summary!$M$25:$M$45,0)),"") -> Qatar Airways | C15: =IFERROR(INDEX(Summary!$C$25:$C$45,MATCH($B15,Summary!$A$25:$A$45,0)),0) -> 37 | D15: =IFERROR(INDEX(Summary!$K$25:$K$45,MATCH($B15,Summary!$A$25:$A$45,0)),0) -> 0 | E15: =C15-D15 -> 37 | F15: =IFERROR(INDEX(Summary!$D$25:$D$45,MATCH($B15,Summary!$A$25:$A$45,0)),0) -> 66 | H15: Aggregator BOGO | I15: =SUMPRODUCT((Summary!$B$25:$B$45="Aggregator BOGO")*Summary!$C$25:$C$45) -> 55 | J15: =SUMIFS('Weekly Log'!$J$5:$J$636,'Weekly Log'!$G$5:$G$636,$C$4,'Weekly Log'!$M$5:$M$636,"Aggregator BOGO") -> 55 | K15: =SUMIFS('Weekly Log'!$K$5:$K$636,'Weekly Log'!$G$5:$G$636,$C$4,'Weekly Log'!$M$5:$M$636,"Aggregator BOGO") -> 8668 | L15: =IF(I15=0,0,K15/I15) -> 157.6
B16: =IFERROR(INDEX(Summary!$A$25:$A$45,MATCH(LARGE(Summary!$M$25:$M$45,3),Summary!$M$25:$M$45,0)),"") -> Urban Point | C16: =IFERROR(INDEX(Summary!$C$25:$C$45,MATCH($B16,Summary!$A$25:$A$45,0)),0) -> 27 | D16: =IFERROR(INDEX(Summary!$K$25:$K$45,MATCH($B16,Summary!$A$25:$A$45,0)),0) -> 0 | E16: =C16-D16 -> 27 | F16: =IFERROR(INDEX(Summary!$D$25:$D$45,MATCH($B16,Summary!$A$25:$A$45,0)),0) -> 40 | H16: Total | I16: =SUM(I14:I15) -> 194 | J16: =SUM(J14:J15) -> 576 | K16: =SUM(K14:K15) -> 12750.5
B17: =IFERROR(INDEX(Summary!$A$25:$A$45,MATCH(LARGE(Summary!$M$25:$M$45,4),Summary!$M$25:$M$45,0)),"") -> Public Health Sector (Sogha) | C17: =IFERROR(INDEX(Summary!$C$25:$C$45,MATCH($B17,Summary!$A$25:$A$45,0)),0) -> 25 | D17: =IFERROR(INDEX(Summary!$K$25:$K$45,MATCH($B17,Summary!$A$25:$A$45,0)),0) -> 0 | E17: =C17-D17 -> 25 | F17: =IFERROR(INDEX(Summary!$D$25:$D$45,MATCH($B17,Summary!$A$25:$A$45,0)),0) -> 51
B18: =IFERROR(INDEX(Summary!$A$25:$A$45,MATCH(LARGE(Summary!$M$25:$M$45,5),Summary!$M$25:$M$45,0)),"") -> My Book | C18: =IFERROR(INDEX(Summary!$C$25:$C$45,MATCH($B18,Summary!$A$25:$A$45,0)),0) -> 14 | D18: =IFERROR(INDEX(Summary!$K$25:$K$45,MATCH($B18,Summary!$A$25:$A$45,0)),0) -> 0 | E18: =C18-D18 -> 14 | F18: =IFERROR(INDEX(Summary!$D$25:$D$45,MATCH($B18,Summary!$A$25:$A$45,0)),0) -> 25 | H18: Partners with no usage this month
B19: =IFERROR(INDEX(Summary!$A$25:$A$45,MATCH(LARGE(Summary!$M$25:$M$45,6),Summary!$M$25:$M$45,0)),"") -> Entertainer | C19: =IFERROR(INDEX(Summary!$C$25:$C$45,MATCH($B19,Summary!$A$25:$A$45,0)),0) -> 14 | D19: =IFERROR(INDEX(Summary!$K$25:$K$45,MATCH($B19,Summary!$A$25:$A$45,0)),0) -> 0 | E19: =C19-D19 -> 14 | F19: =IFERROR(INDEX(Summary!$D$25:$D$45,MATCH($B19,Summary!$A$25:$A$45,0)),0) -> 19 | H19: Partner | I19: Mechanism | J19: Last used (month)
B20: =IFERROR(INDEX(Summary!$A$25:$A$45,MATCH(LARGE(Summary!$M$25:$M$45,7),Summary!$M$25:$M$45,0)),"") -> Qatar Foundation | C20: =IFERROR(INDEX(Summary!$C$25:$C$45,MATCH($B20,Summary!$A$25:$A$45,0)),0) -> 13 | D20: =IFERROR(INDEX(Summary!$K$25:$K$45,MATCH($B20,Summary!$A$25:$A$45,0)),0) -> 0 | E20: =C20-D20 -> 13 | F20: =IFERROR(INDEX(Summary!$D$25:$D$45,MATCH($B20,Summary!$A$25:$A$45,0)),0) -> 34 | H20: =IFERROR(INDEX(Summary!$A$25:$A$45,SMALL(Summary!$N$25:$N$45,1)),"") -> Dar App | I20: =IF(H20="","",INDEX('Partner Master'!$C$5:$C$25,MATCH(H20,'Partner Master'!$A$5:$A$25,0))) -> Dar community app | J20: =IF(H20="","",IFERROR(INDEX('Trend Data'!$G$5:$G$2085,MATCH(H20,'Trend Data'!$L$5:$L$2085,0)),"Never")) -> 2026-07
B21: =IFERROR(INDEX(Summary!$A$25:$A$45,MATCH(LARGE(Summary!$M$25:$M$45,8),Summary!$M$25:$M$45,0)),"") -> Qatar Investment Authority | C21: =IFERROR(INDEX(Summary!$C$25:$C$45,MATCH($B21,Summary!$A$25:$A$45,0)),0) -> 12 | D21: =IFERROR(INDEX(Summary!$K$25:$K$45,MATCH($B21,Summary!$A$25:$A$45,0)),0) -> 0 | E21: =C21-D21 -> 12 | F21: =IFERROR(INDEX(Summary!$D$25:$D$45,MATCH($B21,Summary!$A$25:$A$45,0)),0) -> 20 | H21: =IFERROR(INDEX(Summary!$A$25:$A$45,SMALL(Summary!$N$25:$N$45,2)),"") -> Classmate | I21: =IF(H21="","",INDEX('Partner Master'!$C$5:$C$25,MATCH(H21,'Partner Master'!$A$5:$A$25,0))) -> App 9171 | J21: =IF(H21="","",IFERROR(INDEX('Trend Data'!$G$5:$G$2085,MATCH(H21,'Trend Data'!$L$5:$L$2085,0)),"Never")) -> 2026-07
B22: =IFERROR(INDEX(Summary!$A$25:$A$45,MATCH(LARGE(Summary!$M$25:$M$45,9),Summary!$M$25:$M$45,0)),"") -> Aspire | C22: =IFERROR(INDEX(Summary!$C$25:$C$45,MATCH($B22,Summary!$A$25:$A$45,0)),0) -> 4 | D22: =IFERROR(INDEX(Summary!$K$25:$K$45,MATCH($B22,Summary!$A$25:$A$45,0)),0) -> 0 | E22: =C22-D22 -> 4 | F22: =IFERROR(INDEX(Summary!$D$25:$D$45,MATCH($B22,Summary!$A$25:$A$45,0)),0) -> 5 | H22: =IFERROR(INDEX(Summary!$A$25:$A$45,SMALL(Summary!$N$25:$N$45,3)),"") -> MyBenefit | I22: =IF(H22="","",INDEX('Partner Master'!$C$5:$C$25,MATCH(H22,'Partner Master'!$A$5:$A$25,0))) -> Codes mbfua15 / mbfip15 / mbfcb15 / mbfkd15 | J22: =IF(H22="","",IFERROR(INDEX('Trend Data'!$G$5:$G$2085,MATCH(H22,'Trend Data'!$L$5:$L$2085,0)),"Never")) -> Never
B23: =IFERROR(INDEX(Summary!$A$25:$A$45,MATCH(LARGE(Summary!$M$25:$M$45,10),Summary!$M$25:$M$45,0)),"") -> Al Jazeera Imtiyazat | C23: =IFERROR(INDEX(Summary!$C$25:$C$45,MATCH($B23,Summary!$A$25:$A$45,0)),0) -> 3 | D23: =IFERROR(INDEX(Summary!$K$25:$K$45,MATCH($B23,Summary!$A$25:$A$45,0)),0) -> 0 | E23: =C23-D23 -> 3 | F23: =IFERROR(INDEX(Summary!$D$25:$D$45,MATCH($B23,Summary!$A$25:$A$45,0)),0) -> 6 | H23: =IFERROR(INDEX(Summary!$A$25:$A$45,SMALL(Summary!$N$25:$N$45,4)),"") -> DHL | I23: =IF(H23="","",INDEX('Partner Master'!$C$5:$C$25,MATCH(H23,'Partner Master'!$A$5:$A$25,0))) -> Staff ID | J23: =IF(H23="","",IFERROR(INDEX('Trend Data'!$G$5:$G$2085,MATCH(H23,'Trend Data'!$L$5:$L$2085,0)),"Never")) -> Never
H24: =IFERROR(INDEX(Summary!$A$25:$A$45,SMALL(Summary!$N$25:$N$45,5)),"") -> Huawei | I24: =IF(H24="","",INDEX('Partner Master'!$C$5:$C$25,MATCH(H24,'Partner Master'!$A$5:$A$25,0))) -> Staff ID | J24: =IF(H24="","",IFERROR(INDEX('Trend Data'!$G$5:$G$2085,MATCH(H24,'Trend Data'!$L$5:$L$2085,0)),"Never")) -> Never
B25: By venue this week | H25: =IFERROR(INDEX(Summary!$A$25:$A$45,SMALL(Summary!$N$25:$N$45,6)),"") -> Qatar Media Corporation | I25: =IF(H25="","",INDEX('Partner Master'!$C$5:$C$25,MATCH(H25,'Partner Master'!$A$5:$A$25,0))) -> Staff ID | J25: =IF(H25="","",IFERROR(INDEX('Trend Data'!$G$5:$G$2085,MATCH(H25,'Trend Data'!$L$5:$L$2085,0)),"Never")) -> 2026-08
B26: Venue | C26: Redemptions | D26: Tickets | E26: Discount QAR | F26: Share | H26: =IFERROR(INDEX(Summary!$A$25:$A$45,SMALL(Summary!$N$25:$N$45,7)),"") -> Snoonu Employees | I26: =IF(H26="","",INDEX('Partner Master'!$C$5:$C$25,MATCH(H26,'Partner Master'!$A$5:$A$25,0))) -> Scity app | J26: =IF(H26="","",IFERROR(INDEX('Trend Data'!$G$5:$G$2085,MATCH(H26,'Trend Data'!$L$5:$L$2085,0)),"Never")) -> 2026-04
B27: Urban Arena | C27: =Summary!I15 -> 67 | D27: =Summary!J15 -> 241 | E27: =Summary!K15 -> 3914.75 | F27: =IF($C$31=0,0,C27/$C$31) -> 0.34536082 | H27: =IFERROR(INDEX(Summary!$A$25:$A$45,SMALL(Summary!$N$25:$N$45,8)),"") | I27: =IF(H27="","",INDEX('Partner Master'!$C$5:$C$25,MATCH(H27,'Partner Master'!$A$5:$A$25,0))) | J27: =IF(H27="","",IFERROR(INDEX('Trend Data'!$G$5:$G$2085,MATCH(H27,'Trend Data'!$L$5:$L$2085,0)),"Never"))
B28: InflataPark | C28: =Summary!I16 -> 58 | D28: =Summary!J16 -> 148 | E28: =Summary!K16 -> 3273.5 | F28: =IF($C$31=0,0,C28/$C$31) -> 0.29896907
B29: Kids City Driving School | C29: =Summary!I17 -> 45 | D29: =Summary!J17 -> 158 | E29: =Summary!K17 -> 3230.75 | F29: =IF($C$31=0,0,C29/$C$31) -> 0.23195876
B30: Crayons & Bricks Vendome | C30: =Summary!I18 -> 24 | D30: =Summary!J18 -> 29 | E30: =Summary!K18 -> 2331.5 | F30: =IF($C$31=0,0,C30/$C$31) -> 0.12371134
B31: Total | C31: =SUM(C27:C30) -> 194 | D31: =SUM(D27:D30) -> 576 | E31: =SUM(E27:E30) -> 12750.5 | F31: 1
B33: Weekly trend (partner redemptions)
B34: Week | C34: Redemptions | D34: Tickets | E34: Discount QAR | F34: Aggregator BOGO
B35: =IF(36<=VALUE(RIGHT($C$4,2)),LEFT($C$4,6)&TEXT(36,"00"),"") -> 2026-W36 | C35: =IF(B35="","",SUMIFS('Weekly Log'!$H$5:$H$636,'Weekly Log'!$G$5:$G$636,B35,'Weekly Log'!$M$5:$M$636,"Corporate discount")+SUMIFS('Weekly Log'!$H$5:$H$636,'Weekly Log'!$G$5:$G$636,B35,'Weekly Log'!$M$5:$M$636,"Aggregator BOGO")) -> 0 | D35: =IF(B35="","",SUMIFS('Weekly Log'!$J$5:$J$636,'Weekly Log'!$G$5:$G$636,B35,'Weekly Log'!$M$5:$M$636,"Corporate discount")+SUMIFS('Weekly Log'!$J$5:$J$636,'Weekly Log'!$G$5:$G$636,B35,'Weekly Log'!$M$5:$M$636,"Aggregator BOGO")) -> 0 | E35: =IF(B35="","",SUMIFS('Weekly Log'!$K$5:$K$636,'Weekly Log'!$G$5:$G$636,B35,'Weekly Log'!$M$5:$M$636,"Corporate discount")+SUMIFS('Weekly Log'!$K$5:$K$636,'Weekly Log'!$G$5:$G$636,B35,'Weekly Log'!$M$5:$M$636,"Aggregator BOGO")) -> 0 | F35: =IF(B35="","",SUMIFS('Weekly Log'!$H$5:$H$636,'Weekly Log'!$G$5:$G$636,B35,'Weekly Log'!$M$5:$M$636,"Aggregator BOGO")) -> 0
B36: =IF(37<=VALUE(RIGHT($C$4,2)),LEFT($C$4,6)&TEXT(37,"00"),"") -> 2026-W37 | C36: =IF(B36="","",SUMIFS('Weekly Log'!$H$5:$H$636,'Weekly Log'!$G$5:$G$636,B36,'Weekly Log'!$M$5:$M$636,"Corporate discount")+SUMIFS('Weekly Log'!$H$5:$H$636,'Weekly Log'!$G$5:$G$636,B36,'Weekly Log'!$M$5:$M$636,"Aggregator BOGO")) -> 194 | D36: =IF(B36="","",SUMIFS('Weekly Log'!$J$5:$J$636,'Weekly Log'!$G$5:$G$636,B36,'Weekly Log'!$M$5:$M$636,"Corporate discount")+SUMIFS('Weekly Log'!$J$5:$J$636,'Weekly Log'!$G$5:$G$636,B36,'Weekly Log'!$M$5:$M$636,"Aggregator BOGO")) -> 576 | E36: =IF(B36="","",SUMIFS('Weekly Log'!$K$5:$K$636,'Weekly Log'!$G$5:$G$636,B36,'Weekly Log'!$M$5:$M$636,"Corporate discount")+SUMIFS('Weekly Log'!$K$5:$K$636,'Weekly Log'!$G$5:$G$636,B36,'Weekly Log'!$M$5:$M$636,"Aggregator BOGO")) -> 12750.5 | F36: =IF(B36="","",SUMIFS('Weekly Log'!$H$5:$H$636,'Weekly Log'!$G$5:$G$636,B36,'Weekly Log'!$M$5:$M$636,"Aggregator BOGO")) -> 55
B37: =IF(38<=VALUE(RIGHT($C$4,2)),LEFT($C$4,6)&TEXT(38,"00"),"") | C37: =IF(B37="","",SUMIFS('Weekly Log'!$H$5:$H$636,'Weekly Log'!$G$5:$G$636,B37,'Weekly Log'!$M$5:$M$636,"Corporate discount")+SUMIFS('Weekly Log'!$H$5:$H$636,'Weekly Log'!$G$5:$G$636,B37,'Weekly Log'!$M$5:$M$636,"Aggregator BOGO")) | D37: =IF(B37="","",SUMIFS('Weekly Log'!$J$5:$J$636,'Weekly Log'!$G$5:$G$636,B37,'Weekly Log'!$M$5:$M$636,"Corporate discount")+SUMIFS('Weekly Log'!$J$5:$J$636,'Weekly Log'!$G$5:$G$636,B37,'Weekly Log'!$M$5:$M$636,"Aggregator BOGO")) | E37: =IF(B37="","",SUMIFS('Weekly Log'!$K$5:$K$636,'Weekly Log'!$G$5:$G$636,B37,'Weekly Log'!$M$5:$M$636,"Corporate discount")+SUMIFS('Weekly Log'!$K$5:$K$636,'Weekly Log'!$G$5:$G$636,B37,'Weekly Log'!$M$5:$M$636,"Aggregator BOGO")) | F37: =IF(B37="","",SUMIFS('Weekly Log'!$H$5:$H$636,'Weekly Log'!$G$5:$G$636,B37,'Weekly Log'!$M$5:$M$636,"Aggregator BOGO"))
B38: =IF(39<=VALUE(RIGHT($C$4,2)),LEFT($C$4,6)&TEXT(39,"00"),"") | C38: =IF(B38="","",SUMIFS('Weekly Log'!$H$5:$H$636,'Weekly Log'!$G$5:$G$636,B38,'Weekly Log'!$M$5:$M$636,"Corporate discount")+SUMIFS('Weekly Log'!$H$5:$H$636,'Weekly Log'!$G$5:$G$636,B38,'Weekly Log'!$M$5:$M$636,"Aggregator BOGO")) | D38: =IF(B38="","",SUMIFS('Weekly Log'!$J$5:$J$636,'Weekly Log'!$G$5:$G$636,B38,'Weekly Log'!$M$5:$M$636,"Corporate discount")+SUMIFS('Weekly Log'!$J$5:$J$636,'Weekly Log'!$G$5:$G$636,B38,'Weekly Log'!$M$5:$M$636,"Aggregator BOGO")) | E38: =IF(B38="","",SUMIFS('Weekly Log'!$K$5:$K$636,'Weekly Log'!$G$5:$G$636,B38,'Weekly Log'!$M$5:$M$636,"Corporate discount")+SUMIFS('Weekly Log'!$K$5:$K$636,'Weekly Log'!$G$5:$G$636,B38,'Weekly Log'!$M$5:$M$636,"Aggregator BOGO")) | F38: =IF(B38="","",SUMIFS('Weekly Log'!$H$5:$H$636,'Weekly Log'!$G$5:$G$636,B38,'Weekly Log'!$M$5:$M$636,"Aggregator BOGO"))
B39: =IF(40<=VALUE(RIGHT($C$4,2)),LEFT($C$4,6)&TEXT(40,"00"),"") | C39: =IF(B39="","",SUMIFS('Weekly Log'!$H$5:$H$636,'Weekly Log'!$G$5:$G$636,B39,'Weekly Log'!$M$5:$M$636,"Corporate discount")+SUMIFS('Weekly Log'!$H$5:$H$636,'Weekly Log'!$G$5:$G$636,B39,'Weekly Log'!$M$5:$M$636,"Aggregator BOGO")) | D39: =IF(B39="","",SUMIFS('Weekly Log'!$J$5:$J$636,'Weekly Log'!$G$5:$G$636,B39,'Weekly Log'!$M$5:$M$636,"Corporate discount")+SUMIFS('Weekly Log'!$J$5:$J$636,'Weekly Log'!$G$5:$G$636,B39,'Weekly Log'!$M$5:$M$636,"Aggregator BOGO")) | E39: =IF(B39="","",SUMIFS('Weekly Log'!$K$5:$K$636,'Weekly Log'!$G$5:$G$636,B39,'Weekly Log'!$M$5:$M$636,"Corporate discount")+SUMIFS('Weekly Log'!$K$5:$K$636,'Weekly Log'!$G$5:$G$636,B39,'Weekly Log'!$M$5:$M$636,"Aggregator BOGO")) | F39: =IF(B39="","",SUMIFS('Weekly Log'!$H$5:$H$636,'Weekly Log'!$G$5:$G$636,B39,'Weekly Log'!$M$5:$M$636,"Aggregator BOGO"))
B40: =IF(41<=VALUE(RIGHT($C$4,2)),LEFT($C$4,6)&TEXT(41,"00"),"") | C40: =IF(B40="","",SUMIFS('Weekly Log'!$H$5:$H$636,'Weekly Log'!$G$5:$G$636,B40,'Weekly Log'!$M$5:$M$636,"Corporate discount")+SUMIFS('Weekly Log'!$H$5:$H$636,'Weekly Log'!$G$5:$G$636,B40,'Weekly Log'!$M$5:$M$636,"Aggregator BOGO")) | D40: =IF(B40="","",SUMIFS('Weekly Log'!$J$5:$J$636,'Weekly Log'!$G$5:$G$636,B40,'Weekly Log'!$M$5:$M$636,"Corporate discount")+SUMIFS('Weekly Log'!$J$5:$J$636,'Weekly Log'!$G$5:$G$636,B40,'Weekly Log'!$M$5:$M$636,"Aggregator BOGO")) | E40: =IF(B40="","",SUMIFS('Weekly Log'!$K$5:$K$636,'Weekly Log'!$G$5:$G$636,B40,'Weekly Log'!$M$5:$M$636,"Corporate discount")+SUMIFS('Weekly Log'!$K$5:$K$636,'Weekly Log'!$G$5:$G$636,B40,'Weekly Log'!$M$5:$M$636,"Aggregator BOGO")) | F40: =IF(B40="","",SUMIFS('Weekly Log'!$H$5:$H$636,'Weekly Log'!$G$5:$G$636,B40,'Weekly Log'!$M$5:$M$636,"Aggregator BOGO"))
B41: =IF(42<=VALUE(RIGHT($C$4,2)),LEFT($C$4,6)&TEXT(42,"00"),"") | C41: =IF(B41="","",SUMIFS('Weekly Log'!$H$5:$H$636,'Weekly Log'!$G$5:$G$636,B41,'Weekly Log'!$M$5:$M$636,"Corporate discount")+SUMIFS('Weekly Log'!$H$5:$H$636,'Weekly Log'!$G$5:$G$636,B41,'Weekly Log'!$M$5:$M$636,"Aggregator BOGO")) | D41: =IF(B41="","",SUMIFS('Weekly Log'!$J$5:$J$636,'Weekly Log'!$G$5:$G$636,B41,'Weekly Log'!$M$5:$M$636,"Corporate discount")+SUMIFS('Weekly Log'!$J$5:$J$636,'Weekly Log'!$G$5:$G$636,B41,'Weekly Log'!$M$5:$M$636,"Aggregator BOGO")) | E41: =IF(B41="","",SUMIFS('Weekly Log'!$K$5:$K$636,'Weekly Log'!$G$5:$G$636,B41,'Weekly Log'!$M$5:$M$636,"Corporate discount")+SUMIFS('Weekly Log'!$K$5:$K$636,'Weekly Log'!$G$5:$G$636,B41,'Weekly Log'!$M$5:$M$636,"Aggregator BOGO")) | F41: =IF(B41="","",SUMIFS('Weekly Log'!$H$5:$H$636,'Weekly Log'!$G$5:$G$636,B41,'Weekly Log'!$M$5:$M$636,"Aggregator BOGO"))
B42: =IF(43<=VALUE(RIGHT($C$4,2)),LEFT($C$4,6)&TEXT(43,"00"),"") | C42: =IF(B42="","",SUMIFS('Weekly Log'!$H$5:$H$636,'Weekly Log'!$G$5:$G$636,B42,'Weekly Log'!$M$5:$M$636,"Corporate discount")+SUMIFS('Weekly Log'!$H$5:$H$636,'Weekly Log'!$G$5:$G$636,B42,'Weekly Log'!$M$5:$M$636,"Aggregator BOGO")) | D42: =IF(B42="","",SUMIFS('Weekly Log'!$J$5:$J$636,'Weekly Log'!$G$5:$G$636,B42,'Weekly Log'!$M$5:$M$636,"Corporate discount")+SUMIFS('Weekly Log'!$J$5:$J$636,'Weekly Log'!$G$5:$G$636,B42,'Weekly Log'!$M$5:$M$636,"Aggregator BOGO")) | E42: =IF(B42="","",SUMIFS('Weekly Log'!$K$5:$K$636,'Weekly Log'!$G$5:$G$636,B42,'Weekly Log'!$M$5:$M$636,"Corporate discount")+SUMIFS('Weekly Log'!$K$5:$K$636,'Weekly Log'!$G$5:$G$636,B42,'Weekly Log'!$M$5:$M$636,"Aggregator BOGO")) | F42: =IF(B42="","",SUMIFS('Weekly Log'!$H$5:$H$636,'Weekly Log'!$G$5:$G$636,B42,'Weekly Log'!$M$5:$M$636,"Aggregator BOGO"))
B43: =IF(44<=VALUE(RIGHT($C$4,2)),LEFT($C$4,6)&TEXT(44,"00"),"") | C43: =IF(B43="","",SUMIFS('Weekly Log'!$H$5:$H$636,'Weekly Log'!$G$5:$G$636,B43,'Weekly Log'!$M$5:$M$636,"Corporate discount")+SUMIFS('Weekly Log'!$H$5:$H$636,'Weekly Log'!$G$5:$G$636,B43,'Weekly Log'!$M$5:$M$636,"Aggregator BOGO")) | D43: =IF(B43="","",SUMIFS('Weekly Log'!$J$5:$J$636,'Weekly Log'!$G$5:$G$636,B43,'Weekly Log'!$M$5:$M$636,"Corporate discount")+SUMIFS('Weekly Log'!$J$5:$J$636,'Weekly Log'!$G$5:$G$636,B43,'Weekly Log'!$M$5:$M$636,"Aggregator BOGO")) | E43: =IF(B43="","",SUMIFS('Weekly Log'!$K$5:$K$636,'Weekly Log'!$G$5:$G$636,B43,'Weekly Log'!$M$5:$M$636,"Corporate discount")+SUMIFS('Weekly Log'!$K$5:$K$636,'Weekly Log'!$G$5:$G$636,B43,'Weekly Log'!$M$5:$M$636,"Aggregator BOGO")) | F43: =IF(B43="","",SUMIFS('Weekly Log'!$H$5:$H$636,'Weekly Log'!$G$5:$G$636,B43,'Weekly Log'!$M$5:$M$636,"Aggregator BOGO"))
B44: =IF(45<=VALUE(RIGHT($C$4,2)),LEFT($C$4,6)&TEXT(45,"00"),"") | C44: =IF(B44="","",SUMIFS('Weekly Log'!$H$5:$H$636,'Weekly Log'!$G$5:$G$636,B44,'Weekly Log'!$M$5:$M$636,"Corporate discount")+SUMIFS('Weekly Log'!$H$5:$H$636,'Weekly Log'!$G$5:$G$636,B44,'Weekly Log'!$M$5:$M$636,"Aggregator BOGO")) | D44: =IF(B44="","",SUMIFS('Weekly Log'!$J$5:$J$636,'Weekly Log'!$G$5:$G$636,B44,'Weekly Log'!$M$5:$M$636,"Corporate discount")+SUMIFS('Weekly Log'!$J$5:$J$636,'Weekly Log'!$G$5:$G$636,B44,'Weekly Log'!$M$5:$M$636,"Aggregator BOGO")) | E44: =IF(B44="","",SUMIFS('Weekly Log'!$K$5:$K$636,'Weekly Log'!$G$5:$G$636,B44,'Weekly Log'!$M$5:$M$636,"Corporate discount")+SUMIFS('Weekly Log'!$K$5:$K$636,'Weekly Log'!$G$5:$G$636,B44,'Weekly Log'!$M$5:$M$636,"Aggregator BOGO")) | F44: =IF(B44="","",SUMIFS('Weekly Log'!$H$5:$H$636,'Weekly Log'!$G$5:$G$636,B44,'Weekly Log'!$M$5:$M$636,"Aggregator BOGO"))
B45: Weeks with no export pasted show as blank; weeks before W36 are not listed.
...

Sheet Read Me
B2: How to update this report every week (10 minutes)
B4: 1. In BookingQube, export the event-wise promo-code report for the ISO week just ended (Monday to Sunday). It must include event_id and event_title, which give the venue. Save as CSV.
B5: 2. Open the Weekly Log tab. Paste the export rows (columns A to K, event-wise export including event_id and event_title) directly below the last filled row. Do not touch columns L to N; they fill themselves.
B6: 3. Once a week also refresh the Month Data tab (current calendar month export, replace from row 5) and, on the first Tuesday of each month, the Trend Data tab (all-months export).
B7: 4. On the Dashboard, type the week you are reporting in C4 (format 2026-W38) and the meeting date in I4.
B8: 5. Check the Dashboard. If a partner shows as Unmapped or Not on master, open Code Mapping and set its Partner, Category and Venue in the yellow cells. New codes appear automatically at the bottom of the list only if you add them there; add one row per new code.
B9: 6. Open MoM Follow-up and update the Status and Update columns for each open point.
B10: 7. Present the Dashboard tab on screen (it is set to print on one landscape page). The Summary tab has the full partner table if management asks for detail.
B12: Definitions
B13: Partner redemptions: number of bookings where a corporate or aggregator promo code was applied. Tickets: entries issued under those bookings. Discount: value given, QAR.
B14: Corporate discount: staff-ID and card partners (15% to 20% on the bill). Aggregator BOGO: Urban Point, My Book, Entertainer, Qatar Living, Classmate free-pass offers.
B15: Internal / promotion codes (loyalty, cafe, Inflatarun, driving licence, media pass) are excluded from all partner totals.
... B19: Yellow cells are inputs. Everything else is a formula; do not overwrite.

Sheet Summary
A1: Corporate Deals and Aggregator Redemptions: Weekly Management Review
A2: All figures are formulas over the data sheets. Partner totals count Corporate discount, Aggregator BOGO and Not on master codes; Internal/promotion codes (loyalty, cafe, Inflatarun, driving licence) and Unmapped codes are excluded and shown separately.
A4: Reporting week | B4: =Dashboard!C4 -> 2026-W37
A5: Current month | B5: 2026-09
A6: Prepared by | B6: Rajan Pathak, Head of Operations (FEC & IT)
A8: Key figures | B8: Redemptions | C8: Tickets | D8: Discount QAR | E8: Active partners
A9: Reporting week (Dashboard!C4) | B9: =(SUMIFS('Weekly Log'!$H$5:$H$636,'Weekly Log'!$G$5:$G$636,Dashboard!$C$4,'Weekly Log'!$M$5:$M$636,"Corporate discount")+SUMIFS('Weekly Log'!$H$5:$H$636,'Weekly Log'!$G$5:$G$636,Dashboard!$C$4,'Weekly Log'!$M$5:$M$636,"Aggregator BOGO")+SUMIFS('Weekly Log'!$H$5:$H$636,'Weekly Log'!$G$5:$G$636,Dashboard!$C$4,'Weekly Log'!$M$5:$M$636,"Not on master")) -> 194 | C9: =(SUMIFS('Weekly Log'!$J$5:$J$636,'Weekly Log'!$G$5:$G$636,Dashboard!$C$4,'Weekly Log'!$M$5:$M$636,"Corporate discount")+SUMIFS('Weekly Log'!$J$5:$J$636,'Weekly Log'!$G$5:$G$636,Dashboard!$C$4,'Weekly Log'!$M$5:$M$636,"Aggregator BOGO")+SUMIFS('Weekly Log'!$J$5:$J$636,'Weekly Log'!$G$5:$G$636,Dashboard!$C$4,'Weekly Log'!$M$5:$M$636,"Not on master")) -> 576 | D9: =(SUMIFS('Weekly Log'!$K$5:$K$636,'Weekly Log'!$G$5:$G$636,Dashboard!$C$4,'Weekly Log'!$M$5:$M$636,"Corporate discount")+SUMIFS('Weekly Log'!$K$5:$K$636,'Weekly Log'!$G$5:$G$636,Dashboard!$C$4,'Weekly Log'!$M$5:$M$636,"Aggregator BOGO")+SUMIFS('Weekly Log'!$K$5:$K$636,'Weekly Log'!$G$5:$G$636,Dashboard!$C$4,'Weekly Log'!$M$5:$M$636,"Not on master")) -> 12750.5 | E9: =SUMPRODUCT((C25:C45>0)*1) -> 12
A10: This month to date | B10: =(SUMIFS('Month Data'!$H$5:$H$42,'Month Data'!$M$5:$M$42,"Corporate discount")+SUMIFS('Month Data'!$H$5:$H$42,'Month Data'!$M$5:$M$42,"Aggregator BOGO")+SUMIFS('Month Data'!$H$5:$H$42,'Month Data'!$M$5:$M$42,"Not on master")) -> 351 | C10: =(SUMIFS('Month Data'!$J$5:$J$42,'Month Data'!$M$5:$M$42,"Corporate discount")+SUMIFS('Month Data'!$J$5:$J$42,'Month Data'!$M$5:$M$42,"Aggregator BOGO")+SUMIFS('Month Data'!$J$5:$J$42,'Month Data'!$M$5:$M$42,"Not on master")) -> 1042 | D10: =(SUMIFS('Month Data'!$K$5:$K$42,'Month Data'!$M$5:$M$42,"Corporate discount")+SUMIFS('Month Data'!$K$5:$K$42,'Month Data'!$M$5:$M$42,"Aggregator BOGO")+SUMIFS('Month Data'!$K$5:$K$42,'Month Data'!$M$5:$M$42,"Not on master")) -> 21132.95 | E10: =SUMPRODUCT((D25:D45>0)*1) -> 14
A11: Previous full month | B11: =(SUMIFS('Trend Data'!$H$5:$H$2085,'Trend Data'!$G$5:$G$2085,$B$21,'Trend Data'!$M$5:$M$2085,"Corporate discount")+SUMIFS('Trend Data'!$H$5:$H$2085,'Trend Data'!$G$5:$G$2085,$B$21,'Trend Data'!$M$5:$M$2085,"Aggregator BOGO")+SUMIFS('Trend Data'!$H$5:$H$2085,'Trend Data'!$G$5:$G$2085,$B$21,'Trend Data'!$M$5:$M$2085,"Not on master")) -> 873 | C11: =(SUMIFS('Trend Data'!$J$5:$J$2085,'Trend Data'!$G$5:$G$2085,$B$21,'Trend Data'!$M$5:$M$2085,"Corporate discount")+SUMIFS('Trend Data'!$J$5:$J$2085,'Trend Data'!$G$5:$G$2085,$B$21,'Trend Data'!$M$5:$M$2085,"Aggregator BOGO")+SUMIFS('Trend Data'!$J$5:$J$2085,'Trend Data'!$G$5:$G$2085,$B$21,'Trend Data'!$M$5:$M$2085,"Not on master")) -> 2645 | D11: =(SUMIFS('Trend Data'!$K$5:$K$2085,'Trend Data'!$G$5:$G$2085,$B$21,'Trend Data'!$M$5:$M$2085,"Corporate discount")+SUMIFS('Trend Data'!$K$5:$K$2085,'Trend Data'!$G$5:$G$2085,$B$21,'Trend Data'!$M$5:$M$2085,"Aggregator BOGO")+SUMIFS('Trend Data'!$K$5:$K$2085,'Trend Data'!$G$5:$G$2085,$B$21,'Trend Data'!$M$5:$M$2085,"Not on master")) -> 55769.7 | E11: =SUMPRODUCT((H25:H45>0)*1) -> 14
A13: Category split, month to date | H13: Venue split (event title from the export)
A14: Category | B14: Redemptions | C14: Tickets | D14: Discount QAR | E14: Share of redemptions | F14: Share of discount | G14: Discount per redemption | H14: Venue | I14: Week: redemptions | J14: Week: tickets | K14: Week: discount QAR | L14: Month: redemptions | M14: Month: discount QAR
A15: Corporate discount | B15: =SUMIFS('Month Data'!$H$5:$H$42,'Month Data'!$M$5:$M$42,$A15) -> 266 | C15: =SUMIFS('Month Data'!$J$5:$J$42,'Month Data'!$M$5:$M$42,$A15) -> 957 | D15: =SUMIFS('Month Data'!$K$5:$K$42,'Month Data'!$M$5:$M$42,$A15) -> 7583.95 | E15: =IF($B$10=0,0,B15/$B$10) -> 0.75783476 | F15: =IF($D$10=0,0,D15/$D$10) -> 0.3588685 | G15: =IF(B15=0,0,D15/B15) -> 28.51109 | H15: Urban Arena | I15: =(SUMIFS('Weekly Log'!$H$5:$H$636,'Weekly Log'!$G$5:$G$636,Dashboard!$C$4,'Weekly Log'!$N$5:$N$636,$H15,'Weekly Log'!$M$5:$M$636,"Corporate discount")+SUMIFS('Weekly Log'!$H$5:$H$636,'Weekly Log'!$G$5:$G$636,Dashboard!$C$4,'Weekly Log'!$N$5:$N$636,$H15,'Weekly Log'!$M$5:$M$636,"Aggregator BOGO")) -> 67 | J15: =(SUMIFS('Weekly Log'!$J$5:$J$636,'Weekly Log'!$G$5:$G$636,Dashboard!$C$4,'Weekly Log'!$N$5:$N$636,$H15,'Weekly Log'!$M$5:$M$636,"Corporate discount")+SUMIFS('Weekly Log'!$J$5:$J$636,'Weekly Log'!$G$5:$G$636,Dashboard!$C$4,'Weekly Log'!$N$5:$N$636,$H15,'Weekly Log'!$M$5:$M$636,"Aggregator BOGO")) -> 241 | K15: =(SUMIFS('Weekly Log'!$K$5:$K$636,'Weekly Log'!$G$5:$G$636,Dashboard!$C$4,'Weekly Log'!$N$5:$N$636,$H15,'Weekly Log'!$M$5:$M$636,"Corporate discount")+SUMIFS('Weekly Log'!$K$5:$K$636,'Weekly Log'!$G$5:$G$636,Dashboard!$C$4,'Weekly Log'!$N$5:$N$636,$H15,'Weekly Log'!$M$5:$M$636,"Aggregator BOGO")) -> 3914.75 | L15: =(SUMIFS('Month Data'!$H$5:$H$42,'Month Data'!$N$5:$N$42,$H15,'Month Data'!$M$5:$M$42,"Corporate discount")+SUMIFS('Month Data'!$H$5:$H$42,'Month Data'!$N$5:$N$42,$H15,'Month Data'!$M$5:$M$42,"Aggregator BOGO")) -> 134 | M15: =(SUMIFS('Month Data'!$K$5:$K$42,'Month Data'!$N$5:$N$42,$H15,'Month Data'!$M$5:$M$42,"Corporate discount")+SUMIFS('Month Data'!$K$5:$K$42,'Month Data'!$N$5:$N$42,$H15,'Month Data'!$M$5:$M$42,"Aggregator BOGO")) -> 7547.95
A16: Aggregator BOGO | B16: =SUMIFS('Month Data'!$H$5:$H$42,'Month Data'!$M$5:$M$42,$A16) -> 85 | C16: =SUMIFS('Month Data'!$J$5:$J$42,'Month Data'!$M$5:$M$42,$A16) -> 85 | D16: =SUMIFS('Month Data'!$K$5:$K$42,'Month Data'!$M$5:$M$42,$A16) -> 13549 | E16: =IF($B$10=0,0,B16/$B$10) -> 0.24216524 | F16: =IF($D$10=0,0,D16/$D$10) -> 0.6411315 | G16: =IF(B16=0,0,D16/B16) -> 159.4 | H16: InflataPark | I16: =(SUMIFS('Weekly Log'!$H$5:$H$636,'Weekly Log'!$G$5:$G$636,Dashboard!$C$4,'Weekly Log'!$N$5:$N$636,$H16,'Weekly Log'!$M$5:$M$636,"Corporate discount")+SUMIFS('Weekly Log'!$H$5:$H$636,'Weekly Log'!$G$5:$G$636,Dashboard!$C$4,'Weekly Log'!$N$5:$N$636,$H16,'Weekly Log'!$M$5:$M$636,"Aggregator BOGO")) -> 58 | J16: =(SUMIFS('Weekly Log'!$J$5:$J$636,'Weekly Log'!$G$5:$G$636,Dashboard!$C$4,'Weekly Log'!$N$5:$N$636,$H16,'Weekly Log'!$M$5:$M$636,"Corporate discount")+SUMIFS('Weekly Log'!$J$5:$J$636,'Weekly Log'!$G$5:$G$636,Dashboard!$C$4,'Weekly Log'!$N$5:$N$636,$H16,'Weekly Log'!$M$5:$M$636,"Aggregator BOGO")) -> 148 | K16: =(SUMIFS('Weekly Log'!$K$5:$K$636,'Weekly Log'!$G$5:$G$636,Dashboard!$C$4,'Weekly Log'!$N$5:$N$636,$H16,'Weekly Log'!$M$5:$M$636,"Corporate discount")+SUMIFS('Weekly Log'!$K$5:$K$636,'Weekly Log'!$G$5:$G$636,Dashboard!$C$4,'Weekly Log'!$N$5:$N$636,$H16,'Weekly Log'!$M$5:$M$636,"Aggregator BOGO")) -> 3273.5 | L16: =(SUMIFS('Month Data'!$H$5:$H$42,'Month Data'!$N$5:$N$42,$H16,'Month Data'!$M$5:$M$42,"Corporate discount")+SUMIFS('Month Data'!$H$5:$H$42,'Month Data'!$N$5:$N$42,$H16,'Month Data'!$M$5:$M$42,"Aggregator BOGO")) -> 112 | M16: =(SUMIFS('Month Data'!$K$5:$K$42,'Month Data'!$N$5:$N$42,$H16,'Month Data'!$M$5:$M$42,"Corporate discount")+SUMIFS('Month Data'!$K$5:$K$42,'Month Data'!$N$5:$N$42,$H16,'Month Data'!$M$5:$M$42,"Aggregator BOGO")) -> 5879.75
A17: Not on master | B17: =SUMIFS('Month Data'!$H$5:$H$42,'Month Data'!$M$5:$M$42,$A17) -> 0 | C17: =SUMIFS('Month Data'!$J$5:$J$42,'Month Data'!$M$5:$M$42,$A17) -> 0 | D17: =SUMIFS('Month Data'!$K$5:$K$42,'Month Data'!$M$5:$M$42,$A17) -> 0 | E17: =IF($B$10=0,0,B17/$B$10) -> 0 | F17: =IF($D$10=0,0,D17/$D$10) -> 0 | G17: =IF(B17=0,0,D17/B17) -> 0 | H17: Kids City Driving School | I17: =(SUMIFS('Weekly Log'!$H$5:$H$636,'Weekly Log'!$G$5:$G$636,Dashboard!$C$4,'Weekly Log'!$N$5:$N$636,$H17,'Weekly Log'!$M$5:$M$636,"Corporate discount")+SUMIFS('Weekly Log'!$H$5:$H$636,'Weekly Log'!$G$5:$G$636,Dashboard!$C$4,'Weekly Log'!$N$5:$N$636,$H17,'Weekly Log'!$M$5:$M$636,"Aggregator BOGO")) -> 45 | J17: =(SUMIFS('Weekly Log'!$J$5:$J$636,'Weekly Log'!$G$5:$G$636,Dashboard!$C$4,'Weekly Log'!$N$5:$N$636,$H17,'Weekly Log'!$M$5:$M$636,"Corporate discount")+SUMIFS('Weekly Log'!$J$5:$J$636,'Weekly Log'!$G$5:$G$636,Dashboard!$C$4,'Weekly Log'!$N$5:$N$636,$H17,'Weekly Log'!$M$5:$M$636,"Aggregator BOGO")) -> 158 | K17: =(SUMIFS('Weekly Log'!$K$5:$K$636,'Weekly Log'!$G$5:$G$636,Dashboard!$C$4,'Weekly Log'!$N$5:$N$636,$H17,'Weekly Log'!$M$5:$M$636,"Corporate discount")+SUMIFS('Weekly Log'!$K$5:$K$636,'Weekly Log'!$G$5:$G$636,Dashboard!$C$4,'Weekly Log'!$N$5:$N$636,$H17,'Weekly Log'!$M$5:$M$636,"Aggregator BOGO")) -> 3230.75 | L17: =(SUMIFS('Month Data'!$H$5:$H$42,'Month Data'!$N$5:$N$42,$H17,'Month Data'!$M$5:$M$42,"Corporate discount")+SUMIFS('Month Data'!$H$5:$H$42,'Month Data'!$N$5:$N$42,$H17,'Month Data'!$M$5:$M$42,"Aggregator BOGO")) -> 68 | M17: =(SUMIFS('Month Data'!$K$5:$K$42,'Month Data'!$N$5:$N$42,$H17,'Month Data'!$M$5:$M$42,"Corporate discount")+SUMIFS('Month Data'!$K$5:$K$42,'Month Data'!$N$5:$N$42,$H17,'Month Data'!$M$5:$M$42,"Aggregator BOGO")) -> 4247.5
A18: Unmapped | B18: =SUMIFS('Month Data'!$H$5:$H$42,'Month Data'!$M$5:$M$42,$A18) -> 0 | C18: =SUMIFS('Month Data'!$J$5:$J$42,'Month Data'!$M$5:$M$42,$A18) -> 0 | D18: =SUMIFS('Month Data'!$K$5:$K$42,'Month Data'!$M$5:$M$42,$A18) -> 0 | E18: =IF($B$10=0,0,B18/$B$10) -> 0 | F18: =IF($D$10=0,0,D18/$D$10) -> 0 | G18: =IF(B18=0,0,D18/B18) -> 0 | H18: Crayons & Bricks Vendome | I18: =(SUMIFS('Weekly Log'!$H$5:$H$636,'Weekly Log'!$G$5:$G$636,Dashboard!$C$4,'Weekly Log'!$N$5:$N$636,$H18,'Weekly Log'!$M$5:$M$636,"Corporate discount")+SUMIFS('Weekly Log'!$H$5:$H$636,'Weekly Log'!$G$5:$G$636,Dashboard!$C$4,'Weekly Log'!$N$5:$N$636,$H18,'Weekly Log'!$M$5:$M$636,"Aggregator BOGO")) -> 24 | J18: =(SUMIFS('Weekly Log'!$J$5:$J$636,'Weekly Log'!$G$5:$G$636,Dashboard!$C$4,'Weekly Log'!$N$5:$N$636,$H18,'Weekly Log'!$M$5:$M$636,"Corporate discount")+SUMIFS('Weekly Log'!$J$5:$J$636,'Weekly Log'!$G$5:$G$636,Dashboard!$C$4,'Weekly Log'!$N$5:$N$636,$H18,'Weekly Log'!$M$5:$M$636,"Aggregator BOGO")) -> 29 | K18: =(SUMIFS('Weekly Log'!$K$5:$K$636,'Weekly Log'!$G$5:$G$636,Dashboard!$C$4,'Weekly Log'!$N$5:$N$636,$H18,'Weekly Log'!$M$5:$M$636,"Corporate discount")+SUMIFS('Weekly Log'!$K$5:$K$636,'Weekly Log'!$G$5:$G$636,Dashboard!$C$4,'Weekly Log'!$N$5:$N$636,$H18,'Weekly Log'!$M$5:$M$636,"Aggregator BOGO")) -> 2331.5 | L18: =(SUMIFS('Month Data'!$H$5:$H$42,'Month Data'!$N$5:$N$42,$H18,'Month Data'!$M$5:$M$42,"Corporate discount")+SUMIFS('Month Data'!$H$5:$H$42,'Month Data'!$N$5:$N$42,$H18,'Month Data'!$M$5:$M$42,"Aggregator BOGO")) -> 37 | M18: =(SUMIFS('Month Data'!$K$5:$K$42,'Month Data'!$N$5:$N$42,$H18,'Month Data'!$M$5:$M$42,"Corporate discount")+SUMIFS('Month Data'!$K$5:$K$42,'Month Data'!$N$5:$N$42,$H18,'Month Data'!$M$5:$M$42,"Aggregator BOGO")) -> 3457.75
H19: Total | I19: =SUM(I15:I18) -> 194 | J19: =SUM(J15:J18) -> 576 | K19: =SUM(K15:K18) -> 12750.5 | L19: =SUM(L15:L18) -> 351 | M19: =SUM(M15:M18) -> 21132.95
A20: Previous full month for comparison
A21: Previous month | B21: 2026-08
A23: Partner performance
A24: Partner | B24: Category | C24: This week: redemptions | D24: Month: redemptions | E24: Month: tickets | F24: Month: discount QAR | G24: Month: discount per redemption | H24: Previous month: redemptions | I24: Change vs previous month | J24: Status this month | K24: Previous week: redemptions | L24: Change vs previous week | M24: Rank helper | N24: No-usage helper
A25: ='Partner Master'!A5 -> Al Jazeera Imtiyazat | B25: ='Partner Master'!B5 -> Corporate discount | C25: =SUMIFS('Weekly Log'!$H$5:$H$636,'Weekly Log'!$G$5:$G$636,Dashboard!$C$4,'Weekly Log'!$L$5:$L$636,$A25) -> 3 | D25: =SUMIFS('Month Data'!$H$5:$H$42,'Month Data'!$L$5:$L$42,$A25) -> 6 | E25: =SUMIFS('Month Data'!$J$5:$J$42,'Month Data'!$L$5:$L$42,$A25) -> 11 | F25: =SUMIFS('Month Data'!$K$5:$K$42,'Month Data'!$L$5:$L$42,$A25) -> 219.75 | G25: =IF(D25=0,0,F25/D25) -> 36.625 | H25: =SUMIFS('Trend Data'!$H$5:$H$2085,'Trend Data'!$L$5:$L$2085,$A25,'Trend Data'!$G$5:$G$2085,$B$21) -> 16 | I25: =D25-H25 -> -10 | J25: =IF(D25=0,"No usage","Active") -> Active | K25: =SUMIFS('Weekly Log'!$H$5:$H$636,'Weekly Log'!$G$5:$G$636,Dashboard!$C$5,'Weekly Log'!$L$5:$L$636,$A25) -> 0 | L25: =C25-K25 -> 3 | M25: =C25+(45-ROW())/1000 -> 3.02 | N25: =IF(D25=0,ROW()-24,"")
A26: ='Partner Master'!A6 -> My Book | B26: ='Partner Master'!B6 -> Aggregator BOGO | C26: =SUMIFS('Weekly Log'!$H$5:$H$636,'Weekly Log'!$G$5:$G$636,Dashboard!$C$4,'Weekly Log'!$L$5:$L$636,$A26) -> 14 | D26: =SUMIFS('Month Data'!$H$5:$H$42,'Month Data'!$L$5:$L$42,$A26) -> 25 | E26: =SUMIFS('Month Data'!$J$5:$J$42,'Month Data'!$L$5:$L$42,$A26) -> 25 | F26: =SUMIFS('Month Data'!$K$5:$K$42,'Month Data'!$L$5:$L$42,$A26) -> 4579 | G26: =IF(D26=0,0,F26/D26) -> 183.16 | H26: =SUMIFS('Trend Data'!$H$5:$H$2085,'Trend Data'!$L$5:$L$2085,$A26,'Trend Data'!$G$5:$G$2085,$B$21) -> 116 | I26: =D26-H26 -> -91 | J26: =IF(D26=0,"No usage","Active") -> Active | K26: =SUMIFS('Weekly Log'!$H$5:$H$636,'Weekly Log'!$G$5:$G$636,Dashboard!$C$5,'Weekly Log'!$L$5:$L$636,$A26) -> 0 | L26: =C26-K26 -> 14 | M26: =C26+(45-ROW())/1000 -> 14.019 | N26: =IF(D26=0,ROW()-24,"")
A27: ='Partner Master'!A7 -> QIB | B27: ='Partner Master'!B7 -> Corporate discount | C27: =SUMIFS('Weekly Log'!$H$5:$H$636,'Weekly Log'!$G$5:$G$636,Dashboard!$C$4,'Weekly Log'!$L$5:$L$636,$A27) -> 2 | D27: =SUMIFS('Month Data'!$H$5:$H$42,'Month Data'!$L$5:$L$42,$A27) -> 5 | E27: =SUMIFS('Month Data'!$J$5:$J$42,'Month Data'!$L$5:$L$42,$A27) -> 21 | F27: =SUMIFS('Month Data'!$K$5:$K$42,'Month Data'!$L$5:$L$42,$A27) -> 174 | G27: =IF(D27=0,0,F27/D27) -> 34.8 | H27: =SUMIFS('Trend Data'!$H$5:$H$2085,'Trend Data'!$L$5:$L$2085,$A27,'Trend Data'!$G$5:$G$2085,$B$21) -> 5 | I27: =D27-H27 -> 0 | J27: =IF(D27=0,"No usage","Active") -> Active | K27: =SUMIFS('Weekly Log'!$H$5:$H$636,'Weekly Log'!$G$5:$G$636,Dashboard!$C$5,'Weekly Log'!$L$5:$L$636,$A27) -> 0 | L27: =C27-K27 -> 2 | M27: =C27+(45-ROW())/1000 -> 2.018 | N27: =IF(D27=0,ROW()-24,"")
A28: ='Partner Master'!A8 -> Dar App | B28: ='Partner Master'!B8 -> Corporate discount | C28: =SUMIFS('Weekly Log'!$H$5:$H$636,'Weekly Log'!$G$5:$G$636,Dashboard!$C$4,'Weekly Log'!$L$5:$L$636,$A28) -> 0 | D28: =SUMIFS('Month Data'!$H$5:$H$42,'Month Data'!$L$5:$L$42,$A28) -> 0 | E28: =SUMIFS('Month Data'!$J$5:$J$42,'Month Data'!$L$5:$L$42,$A28) -> 0 | F28: =SUMIFS('Month Data'!$K$5:$K$42,'Month Data'!$L$5:$L$42,$A28) -> 0 | G28: =IF(D28=0,0,F28/D28) -> 0 | H28: =SUMIFS('Trend Data'!$H$5:$H$2085,'Trend Data'!$L$5:$L$2085,$A28,'Trend Data'!$G$5:$G$2085,$B$21) -> 0 | I28: =D28-H28 -> 0 | J28: =IF(D28=0,"No usage","Active") -> No usage | K28: =SUMIFS('Weekly Log'!$H$5:$H$636,'Weekly Log'!$G$5:$G$636,Dashboard!$C$5,'Weekly Log'!$L$5:$L$636,$A28) -> 0 | L28: =C28-K28 -> 0 | M28: =C28+(45-ROW())/1000 -> 0.017 | N28: =IF(D28=0,ROW()-24,"") -> 4
A29: ='Partner Master'!A9 -> Qatar Airways | B29: ='Partner Master'!B9 -> Corporate discount | C29: =SUMIFS('Weekly Log'!$H$5:$H$636,'Weekly Log'!$G$5:$G$636,Dashboard!$C$4,'Weekly Log'!$L$5:$L$636,$A29) -> 37 | D29: =SUMIFS('Month Data'!$H$5:$H$42,'Month Data'!$L$5:$L$42,$A29) -> 66 | E29: =SUMIFS('Month Data'!$J$5:$J$42,'Month Data'!$L$5:$L$42,$A29) -> 205 | F29: =SUMIFS('Month Data'!$K$5:$K$42,'Month Data'!$L$5:$L$42,$A29) -> 1455 | G29: =IF(D29=0,0,F29/D29) -> 22.045455 | H29: =SUMIFS('Trend Data'!$H$5:$H$2085,'Trend Data'!$L$5:$L$2085,$A29,'Trend Data'!$G$5:$G$2085,$B$21) -> 140 | I29: =D29-H29 -> -74 | J29: =IF(D29=0,"No usage","Active") -> Active | K29: =SUMIFS('Weekly Log'!$H$5:$H$636,'Weekly Log'!$G$5:$G$636,Dashboard!$C$5,'Weekly Log'!$L$5:$L$636,$A29) -> 0 | L29: =C29-K29 -> 37 | M29: =C29+(45-ROW())/1000 -> 37.016 | N29: =IF(D29=0,ROW()-24,"")
A30: ='Partner Master'!A10 -> Entertainer | B30: ='Partner Master'!B10 -> Aggregator BOGO | C30: =SUMIFS('Weekly Log'!$H$5:$H$636,'Weekly Log'!$G$5:$G$636,Dashboard!$C$4,'Weekly Log'!$L$5:$L$636,$A30) -> 14 | D30: =SUMIFS('Month Data'!$H$5:$H$42,'Month Data'!$L$5:$L$42,$A30) -> 19 | E30: =SUMIFS('Month Data'!$J$5:$J$42,'Month Data'!$L$5:$L$42,$A30) -> 19 | F30: =SUMIFS('Month Data'!$K$5:$K$42,'Month Data'!$L$5:$L$42,$A30) -> 2593 | G30: =IF(D30=0,0,F30/D30) -> 136.47368 | H30: =SUMIFS('Trend Data'!$H$5:$H$2085,'Trend Data'!$L$5:$L$2085,$A30,'Trend Data'!$G$5:$G$2085,$B$21) -> 19 | I30: =D30-H30 -> 0 | J30: =IF(D30=0,"No usage","Active") -> Active | K30: =SUMIFS('Weekly Log'!$H$5:$H$636,'Weekly Log'!$G$5:$G$636,Dashboard!$C$5,'Weekly Log'!$L$5:$L$636,$A30) -> 0 | L30: =C30-K30 -> 14 | M30: =C30+(45-ROW())/1000 -> 14.015 | N30: =IF(D30=0,ROW()-24,"")
A31: ='Partner Master'!A11 -> Public Health Sector (Sogha) | B31: ='Partner Master'!B11 -> Corporate discount | C31: =SUMIFS('Weekly Log'!$H$5:$H$636,'Weekly Log'!$G$5:$G$636,Dashboard!$C$4,'Weekly Log'!$L$5:$L$636,$A31) -> 25 | D31: =SUMIFS('Month Data'!$H$5:$H$42,'Month Data'!$L$5:$L$42,$A31) -> 51 | E31: =SUMIFS('Month Data'!$J$5:$J$42,'Month Data'!$L$5:$L$42,$A31) -> 157 | F31: =SUMIFS('Month Data'!$K$5:$K$42,'Month Data'!$L$5:$L$42,$A31) -> 1534 | G31: =IF(D31=0,0,F31/D31) -> 30.078431 | H31: =SUMIFS('Trend Data'!$H$5:$H$2085,'Trend Data'!$L$5:$L$2085,$A31,'Trend Data'!$G$5:$G$2085,$B$21) -> 119 | I31: =D31-H31 -> -68 | J31: =IF(D31=0,"No usage","Active") -> Active | K31: =SUMIFS('Weekly Log'!$H$5:$H$636,'Weekly Log'!$G$5:$G$636,Dashboard!$C$5,'Weekly Log'!$L$5:$L$636,$A31) -> 0 | L31: =C31-K31 -> 25 | M31: =C31+(45-ROW())/1000 -> 25.014 | N31: =IF(D31=0,ROW()-24,"")
A32: ='Partner Master'!A12 -> Urban Point | B32: ='Partner Master'!B12 -> Aggregator BOGO | C32: =SUMIFS('Weekly Log'!$H$5:$H$636,'Weekly Log'!$G$5:$G$636,Dashboard!$C$4,'Weekly Log'!$L$5:$L$636,$A32) -> 27 | D32: =SUMIFS('Month Data'!$H$5:$H$42,'Month Data'!$L$5:$L$42,$A32) -> 40 | E32: =SUMIFS('Month Data'!$J$5:$J$42,'Month Data'!$L$5:$L$42,$A32) -> 40 | F32: =SUMIFS('Month Data'!$K$5:$K$42,'Month Data'!$L$5:$L$42,$A32) -> 6277 | G32: =IF(D32=0,0,F32/D32) -> 156.925 | H32: =SUMIFS('Trend Data'!$H$5:$H$2085,'Trend Data'!$L$5:$L$2085,$A32,'Trend Data'!$G$5:$G$2085,$B$21) -> 69 | I32: =D32-H32 -> -29 | J32: =IF(D32=0,"No usage","Active") -> Active | K32: =SUMIFS('Weekly Log'!$H$5:$H$636,'Weekly Log'!$G$5:$G$636,Dashboard!$C$5,'Weekly Log'!$L$5:$L$636,$A32) -> 0 | L32: =C32-K32 -> 27 | M32: =C32+(45-ROW())/1000 -> 27.013 | N32: =IF(D32=0,ROW()-24,"")
A33: ='Partner Master'!A13 -> Qatar Living Deals | B33: ='Partner Master'!B13 -> Aggregator BOGO | C33: =SUMIFS('Weekly Log'!$H$5:$H$636,'Weekly Log'!$G$5:$G$636,Dashboard!$C$4,'Weekly Log'!$L$5:$L$636,$A33) -> 0 | D33: =SUMIFS('Month Data'!$H$5:$H$42,'Month Data'!$L$5:$L$42,$A33) -> 1 | E33: =SUMIFS('Month Data'!$J$5:$J$42,'Month Data'!$L$5:$L$42,$A33) -> 1 | F33: =SUMIFS('Month Data'!$K$5:$K$42,'Month Data'!$L$5:$L$42,$A33) -> 100 | G33: =IF(D33=0,0,F33/D33) -> 100 | H33: =SUMIFS('Trend Data'!$H$5:$H$2085,'Trend Data'!$L$5:$L$2085,$A33,'Trend Data'!$G$5:$G$2085,$B$21) -> 0 | I33: =D33-H33 -> 1 | J33: =IF(D33=0,"No usage","Active") -> Active | K33: =SUMIFS('Weekly Log'!$H$5:$H$636,'Weekly Log'!$G$5:$G$636,Dashboard!$C$5,'Weekly Log'!$L$5:$L$636,$A33) -> 0 | L33: =C33-K33 -> 0 | M33: =C33+(45-ROW())/1000 -> 0.012 | N33: =IF(D33=0,ROW()-24,"")
A34: ='Partner Master'!A14 -> Imtyazat | B34: ='Partner Master'!B14 -> Corporate discount | C34: =SUMIFS('Weekly Log'!$H$5:$H$636,'Weekly Log'!$G$5:$G$636,Dashboard!$C$4,'Weekly Log'!$L$5:$L$636,$A34) -> 40 | D34: =SUMIFS('Month Data'!$H$5:$H$42,'Month Data'!$L$5:$L$42,$A34) -> 72 | E34: =SUMIFS('Month Data'!$J$5:$J$42,'Month Data'!$L$5:$L$42,$A34) -> 305 | F34: =SUMIFS('Month Data'!$K$5:$K$42,'Month Data'!$L$5:$L$42,$A34) -> 2221.5 | G34: =IF(D34=0,0,F34/D34) -> 30.854167 | H34: =SUMIFS('Trend Data'!$H$5:$H$2085,'Trend Data'!$L$5:$L$2085,$A34,'Trend Data'!$G$5:$G$2085,$B$21) -> 261 | I34: =D34-H34 -> -189 | J34: =IF(D34=0,"No usage","Active") -> Active | K34: =SUMIFS('Weekly Log'!$H$5:$H$636,'Weekly Log'!$G$5:$G$636,Dashboard!$C$5,'Weekly Log'!$L$5:$L$636,$A34) -> 0 | L34: =C34-K34 -> 40 | M34: =C34+(45-ROW())/1000 -> 40.011 | N34: =IF(D34=0,ROW()-24,"")
A35: ='Partner Master'!A15 -> Classmate | B35: ='Partner Master'!B15 -> Aggregator BOGO | C35: =SUMIFS('Weekly Log'!$H$5:$H$636,'Weekly Log'!$G$5:$G$636,Dashboard!$C$4,'Weekly Log'!$L$5:$L$636,$A35) -> 0 | D35: =SUMIFS('Month Data'!$H$5:$H$42,'Month Data'!$L$5:$L$42,$A35) -> 0 | E35: =SUMIFS('Month Data'!$J$5:$J$42,'Month Data'!$L$5:$L$42,$A35) -> 0 | F35: =SUMIFS('Month Data'!$K$5:$K$42,'Month Data'!$L$5:$L$42,$A35) -> 0 | G35: =IF(D35=0,0,F35/D35) -> 0 | H35: =SUMIFS('Trend Data'!$H$5:$H$2085,'Trend Data'!$L$5:$L$2085,$A35,'Trend Data'!$G$5:$G$2085,$B$21) -> 0 | I35: =D35-H35 -> 0 | J35: =IF(D35=0,"No usage","Active") -> No usage | K35: =SUMIFS('Weekly Log'!$H$5:$H$636,'Weekly Log'!$G$5:$G$636,Dashboard!$C$5,'Weekly Log'!$L$5:$L$636,$A35) -> 0 | L35: =C35-K35 -> 0 | M35: =C35+(45-ROW())/1000 -> 0.01 | N35: =IF(D35=0,ROW()-24,"") -> 11
A36: ='Partner Master'!A16 -> MyBenefit | B36: ='Partner Master'!B16 -> Corporate discount | C36: =SUMIFS('Weekly Log'!$H$5:$H$636,'Weekly Log'!$G$5:$G$636,Dashboard!$C$4,'Weekly Log'!$L$5:$L$636,$A36) -> 0 | D36: =SUMIFS('Month Data'!$H$5:$H$42,'Month Data'!$L$5:$L$42,$A36) -> 0 | E36: =SUMIFS('Month Data'!$J$5:$J$42,'Month Data'!$L$5:$L$42,$A36) -> 0 | F36: =SUMIFS('Month Data'!$K$5:$K$42,'Month Data'!$L$5:$L$42,$A36) -> 0 | G36: =IF(D36=0,0,F36/D36) -> 0 | H36: =SUMIFS('Trend Data'!$H$5:$H$2085,'Trend Data'!$L$5:$L$2085,$A36,'Trend Data'!$G$5:$G$2085,$B$21) -> 0 | I36: =D36-H36 -> 0 | J36: =IF(D36=0,"No usage","Active") -> No usage | K36: =SUMIFS('Weekly Log'!$H$5:$H$636,'Weekly Log'!$G$5:$G$636,Dashboard!$C$5,'Weekly Log'!$L$5:$L$636,$A36) -> 0 | L36: =C36-K36 -> 0 | M36: =C36+(45-ROW())/1000 -> 0.009 | N36: =IF(D36=0,ROW()-24,"") -> 12
... A45: ='Partner Master'!A25 -> Snoonu Employees | B45: ='Partner Master'!B25 -> Corporate discount | C45: =SUMIFS('Weekly Log'!$H$5:$H$636,'Weekly Log'!$G$5:$G$636,Dashboard!$C$4,'Weekly Log'!$L$5:$L$636,$A45) -> 0 | D45: =SUMIFS('Month Data'!$H$5:$H$42,'Month Data'!$L$5:$L$42,$A45) -> 0 | E45: =SUMIFS('Month Data'!$J$5:$J$42,'Month Data'!$L$5:$L$42,$A45) -> 0 | F45: =SUMIFS('Month Data'!$K$5:$K$42,'Month Data'!$L$5:$L$42,$A45) -> 0 | G45: =IF(D45=0,0,F45/D45) -> 0 | H45: =SUMIFS('Trend Data'!$H$5:$H$2085,'Trend Data'!$L$5:$L$2085,$A45,'Trend Data'!$G$5:$G$2085,$B$21) -> 0 | I45: =D45-H45 -> 0 | J45: =IF(D45=0,"No usage","Active") -> No usage | K45: =SUMIFS('Weekly Log'!$H$5:$H$636,'Weekly Log'!$G$5:$G$636,Dashboard!$C$5,'Weekly Log'!$L$5:$L$636,$A45) -> 0 | L45: =C45-K45 -> 0 | M45: =C45+(45-ROW())/1000 -> 0 | N45: =IF(D45=0,ROW()-24,"") -> 21
A46: Total (partners on master) | C46: =SUM(C25:C45) -> 194 | D46: =SUM(D25:D45) -> 351 | E46: =SUM(E25:E45) -> 1042 | F46: =SUM(F25:F45) -> 21132.95 | H46: =SUM(H25:H45) -> 873 | I46: =SUM(I25:I45) -> -522
A47: Codes not on master or unmapped (month, excluded from partner totals above) | D47: =SUMIFS('Month Data'!$H$5:$H$42,'Month Data'!$M$5:$M$42,"Not on master")+SUMIFS('Month Data'!$H$5:$H$42,'Month Data'!$M$5:$M$42,"Unmapped") -> 0
A49: Monthly trend, last 13 months (partners only, internal codes excluded)
A50: Month | B50: Redemptions | C50: Tickets | D50: Discount QAR | E50: Corporate discount redemptions | F50: Aggregator BOGO redemptions
A51: 2025-09 | B51: =SUMIFS('Trend Data'!$H$5:$H$2085,'Trend Data'!$G$5:$G$2085,$A51,'Trend Data'!$M$5:$M$2085,"<>Internal / promotion") -> 309 | C51: =SUMIFS('Trend Data'!$J$5:$J$2085,'Trend Data'!$G$5:$G$2085,$A51,'Trend Data'!$M$5:$M$2085,"<>Internal / promotion") -> 340 | D51: =SUMIFS('Trend Data'!$K$5:$K$2085,'Trend Data'!$G$5:$G$2085,$A51,'Trend Data'!$M$5:$M$2085,"<>Internal / promotion") -> 47609.5 | E51: =SUMIFS('Trend Data'!$H$5:$H$2085,'Trend Data'!$G$5:$G$2085,$A51,'Trend Data'!$M$5:$M$2085,"Corporate discount") -> 30 | F51: =SUMIFS('Trend Data'!$H$5:$H$2085,'Trend Data'!$G$5:$G$2085,$A51,'Trend Data'!$M$5:$M$2085,"Aggregator BOGO") -> 259
A52: 2025-10 | B52: =SUMIFS('Trend Data'!$H$5:$H$2085,'Trend Data'!$G$5:$G$2085,$A52,'Trend Data'!$M$5:$M$2085,"<>Internal / promotion") -> 428 | C52: =SUMIFS('Trend Data'!$J$5:$J$2085,'Trend Data'!$G$5:$G$2085,$A52,'Trend Data'!$M$5:$M$2085,"<>Internal / promotion") -> 456 | D52: =SUMIFS('Trend Data'!$K$5:$K$2085,'Trend Data'!$G$5:$G$2085,$A52,'Trend Data'!$M$5:$M$2085,"<>Internal / promotion") -> 70015 | E52: =SUMIFS('Trend Data'!$H$5:$H$2085,'Trend Data'!$G$5:$G$2085,$A52,'Trend Data'!$M$5:$M$2085,"Corporate discount") -> 20 | F52: =SUMIFS('Trend Data'!$H$5:$H$2085,'Trend Data'!$G$5:$G$2085,$A52,'Trend Data'!$M$5:$M$2085,"Aggregator BOGO") -> 388
A53: 2025-11 | B53: =SUMIFS('Trend Data'!$H$5:$H$2085,'Trend Data'!$G$5:$G$2085,$A53,'Trend Data'!$M$5:$M$2085,"<>Internal / promotion") -> 201 | C53: =SUMIFS('Trend Data'!$J$5:$J$2085,'Trend Data'!$G$5:$G$2085,$A53,'Trend Data'!$M$5:$M$2085,"<>Internal / promotion") -> 222 | D53: =SUMIFS('Trend Data'!$K$5:$K$2085,'Trend Data'!$G$5:$G$2085,$A53,'Trend Data'!$M$5:$M$2085,"<>Internal / promotion") -> 29360.5 | E53: =SUMIFS('Trend Data'!$H$5:$H$2085,'Trend Data'!$G$5:$G$2085,$A53,'Trend Data'!$M$5:$M$2085,"Corporate discount") -> 16 | F53: =SUMIFS('Trend Data'!$H$5:$H$2085,'Trend Data'!$G$5:$G$2085,$A53,'Trend Data'!$M$5:$M$2085,"Aggregator BOGO") -> 164
...

Sheet Code Mapping
A1: Promo code mapping (edit the blue cells; every other sheet recalculates)
A2: Partner, Category and Venue were assigned from the code and its description. Yellow cells are editable inputs. "Not specified" means the code carries no venue; add the venue in BookingQube and here.
A4: Promo code | B4: Description (from system) | C4: Company field | D4: Partner | E4: Category | F4: Venue | G4: Last used (month) | H4: Uses, last 12 months | I4: Mapping source
A5: cafe50 | B5: 50% off on cafe | D5: Internal / promotion | E5: Internal / promotion | F5: Cafe | G5: 2026-09 | H5: 591 | I5: Derived from code and description
A6: KCDSIMTYD | B6: Imtyazat 15% Discount | C6: E3 | D6: Imtyazat | E6: Corporate discount | F6: KDS | G6: 2026-08 | H6: 519 | I6: Derived from code and description
A7: UPIP100 | B7: InflataPark urban point 100% | D7: Urban Point | E7: Aggregator BOGO | F7: InflataPark | G7: 2026-04 | H7: 516 | I7: Derived from code and description
A8: MBIP100 | B8: InflataPark mybook 100% | D8: My Book | E8: Aggregator BOGO | F8: InflataPark | G8: 2026-04 | H8: 454 | I8: Derived from code and description
A9: INFIMTYD | B9: Imtyazat 15% Discount | C9: E3 | D9: Imtyazat | E9: Corporate discount | F9: InflataPark | G9: 2026-09 | H9: 433 | I9: Derived from code and description
A10: UENA | B10: Qatar Airways 15% Discount | D10: Qatar Airways | E10: Corporate discount | F10: Not specified | G10: 2026-09 | H10: 282 | I10: Derived from code and description
A11: ARNB | B11: Qatar Foundation 15% Discount | C11: E3 | D11: Qatar Foundation | E11: Corporate discount | F11: Not specified | G11: 2026-09 | H11: 270 | I11: Derived from code and description
A12: UNAR | B12: Public Health Sector Employees 20% Discount | D12: Public Health Sector (Sogha) | E12: Corporate discount | F12: Not specified | G12: 2026-09 | H12: 257 | I12: Derived from code and description
A13: INFPHSED | B13: Public Health Sector Employees 20% Discount | D13: Public Health Sector (Sogha) | E13: Corporate discount | F13: InflataPark | G13: 2026-09 | H13: 254 | I13: Derived from code and description
A14: INFQAD | B14: Qatar Airways 15% Discount | D14: Qatar Airways | E14: Corporate discount | F14: InflataPark | G14: 2026-09 | H14: 248 | I14: Derived from code and description
A15: EIP100 | B15: InflataPark entertainer 100% | D15: Entertainer | E15: Aggregator BOGO | F15: InflataPark | G15: 2026-04 | H15: 210 | I15: Derived from code and description
A16: KCDIMTIYAZAT15 | B16: Imtiyazat 15% Discount | C16: E3 | D16: Imtyazat | E16: Corporate discount | F16: KDS | G16: 2026-09 | H16: 198 | I16: Derived from code and description
A17: UBOFFM | B17: My Book BOGO | D17: My Book | E17: Aggregator BOGO | F17: Not specified | G17: 2026-09 | H17: 177 | I17: Derived from code and description
A18: UGBOGU | B18: Urban Point BOGO | D18: Urban Point | E18: Aggregator BOGO | F18: Not specified | G18: 2026-09 | H18: 157 | I18: Derived from code and description
A19: CGBOGU | B19: Urban Point BOGO | D19: Urban Point | E19: Aggregator BOGO | F19: C&B (unspecified mall) | G19: 2026-09 | H19: 152 | I19: Derived from code and description
A20: UPVD | B20: urban point for vendom 100% | D20: Urban Point | E20: Aggregator BOGO | F20: C&B Vendome | G20: 2026-04 | H20: 140 | I20: Derived from code and description
A21: UHBP100 | B21: KDS urban point 100% | D21: Urban Point | E21: Aggregator BOGO | F21: KDS | G21: 2026-04 | H21: 113 | I21: Derived from code and description
A22: CBOGOE | B22: Entertainer BOGO | D22: Entertainer | E22: Aggregator BOGO | F22: C&B (unspecified mall) | G22: 2026-09 | H22: 102 | I22: Derived from code and description
A23: USBP100 | B23: KDS urban point 100% | D23: Urban Point | E23: Aggregator BOGO | F23: KDS | G23: 2026-03 | H23: 99 | I23: Derived from code and description
A24: EBOGO | D24: Entertainer | E24: Aggregator BOGO | F24: Not specified | G24: 2026-04 | H24: 97 | I24: Derived from code and description
A25: MYBVD | D25: My Book | E25: Aggregator BOGO | F25: C&B Vendome | G25: 2026-09 | H25: 94 | I25: Confirmed by Operations, Sep 2026
A26: BHBP100 | B26: KDS mybook 100% | D26: My Book | E26: Aggregator BOGO | F26: KDS | G26: 2026-04 | H26: 85 | I26: Derived from code and description
A27: RENA | B27: Imtyazat 15% Discount | D27: Imtyazat | E27: Corporate discount | F27: Not specified | G27: 2026-09 | H27: 85 | I27: Derived from code and description
A28: pp20 | D28: Internal / promotion | E28: Internal / promotion | F28: Not specified | G28: 2025-12 | H28: 63 | I28: Derived from code and description
A29: KDSBOGOM | C29: E3 | D29: My Book | E29: Aggregator BOGO | F29: KDS | G29: 2026-09 | H29: 62 | I29: Confirmed by Operations, Sep 2026
A30: INFQFD | B30: Qatar Foundation 15% Discount | D30: Qatar Foundation | E30: Corporate discount | F30: InflataPark | G30: 2026-09 | H30: 54 | I30: Derived from code and description
A31: loyaltykds | B31: loyalty pass free city pass | C31: E3 | D31: Internal / promotion | E31: Internal / promotion | F31: KDS | G31: 2026-09 | H31: 54 | I31: Derived from code and description
A32: KCDSURBOGO | B32: Urban Point BOGO | D32: Urban Point | E32: Aggregator BOGO | F32: KDS | G32: 2026-07 | H32: 53 | I32: Derived from code and description
A33: QAIP15 | B33: QATAR AIRWAYS INFLATAPARK 15% | D33: Qatar Airways | E33: Corporate discount | F33: InflataPark | G33: 2026-04 | H33: 45 | I33: Derived from code and description
A34: dmqnb15 | C34: QNB | D34: QNB Rewards | E34: Corporate discount | F34: Not specified | G34: 2026-09 | H34: 44 | I34: Confirmed by Operations, Sep 2026
A35: BSBP100 | B35: KDS mybook 100% | D35: My Book | E35: Aggregator BOGO | F35: KDS | G35: 2025-12 | H35: 42 | I35: Derived from code and description
A36: ESBP100 | B36: KDS entertainer 100% | D36: Entertainer | E36: Aggregator BOGO | F36: KDS | G36: 2026-03 | H36: 42 | I36: Derived from code and description
A37: ARNA | B37: Aspire 15% Discount | D37: Aspire | E37: Corporate discount | F37: Not specified | G37: 2026-09 | H37: 41 | I37: Derived from code and description
A38: zub50 | B38: Aspire Zubara 50% | D38: Internal / promotion | E38: Internal / promotion | F38: Aspire Carousel | G38: 2026-01 | H38: 40 | I38: Derived from code and description
A39: DL30 | B39: Driving License 30% | D39: Internal / promotion | E39: Internal / promotion | F39: Not specified | G39: 2026-04 | H39: 36 | I39: Derived from code and description
A40: INFUPBOGO2 | C40: E3 | D40: Urban Point | E40: Aggregator BOGO | F40: InflataPark | G40: 2026-09 | H40: 35 | I40: Confirmed by Operations, Sep 2026
A41: INFUPBOGO | B41: Urban Point BOGO | D41: Urban Point | E41: Aggregator BOGO | F41: InflataPark | G41: 2026-07 | H41: 33 | I41: Derived from code and description
...

Sheet Partner Master
A1: Partner master (from the Corporate Deals Google Sheet)
A2: Source: Corporate Deals sheet, both tabs. Add new partners here and in Code Mapping.
A4: Partner | B4: Category | C4: Redemption mechanism
A5: Al Jazeera Imtiyazat | B5: Corporate discount | C5: Staff ID
A6: My Book | B6: Aggregator BOGO | C6: App PIN 9247
A7: QIB | B7: Corporate discount | C7: QIB cardholders
A8: Dar App | B8: Corporate discount | C8: Dar community app
A9: Qatar Airways | B9: Corporate discount | C9: Staff ID
A10: Entertainer | B10: Aggregator BOGO | C10: App 9581
A11: Public Health Sector (Sogha) | B11: Corporate discount | C11: Sogha card ID
A12: Urban Point | B12: Aggregator BOGO | C12: App 7654
A13: Qatar Living Deals | B13: Aggregator BOGO | C13: Qatar Living Deals app
A14: Imtyazat | B14: Corporate discount | C14: Imtyazat ID card
A15: Classmate | B15: Aggregator BOGO | C15: App 9171
... A25: Snoonu Employees | B25: Corporate discount | C25: Scity app

Sheet Weekly Log
A1: Weekly Log: raw export from BookingQube plus lookup columns
A2: Weekly log: paste each new weekly export below the last filled row (columns A to I). Formulas cover 600 spare rows. The Dashboard reads the week named in Dashboard!C4.
A4: promocode_id | B4: promocode | C4: description | D4: company_name | E4: event_id | F4: event_title | G4: period_week | H4: times_used | I4: booking_lines | J4: tickets | K4: total_discount | L4: Partner | M4: Category | N4: Venue
A5: 8070 | B5: ARNA | C5: Aspire 15% Discount | E5: 133 | F5: Urban Arena | G5: 2026-W37 | H5: 3 | I5: 17 | J5: 17 | K5: 126.75 | L5: =IF($B5="","",IFERROR(INDEX('Code Mapping'!$D$5:$D$1753,MATCH($B5,'Code Mapping'!$A$5:$A$1753,0)),"Unmapped")) -> Aspire | M5: =IF($B5="","",IFERROR(INDEX('Code Mapping'!$E$5:$E$1753,MATCH($B5,'Code Mapping'!$A$5:$A$1753,0)),"Unmapped")) -> Corporate discount | N5: =IF($F5="","",$F5) -> Urban Arena
A6: 8079 | B6: ARNB | C6: Qatar Foundation 15% Discount | D6: E3 | E6: 133 | F6: Urban Arena | G6: 2026-W37 | H6: 10 | I6: 54 | J6: 54 | K6: 464.25 | L6: =IF($B6="","",IFERROR(INDEX('Code Mapping'!$D$5:$D$1753,MATCH($B6,'Code Mapping'!$A$5:$A$1753,0)),"Unmapped")) -> Qatar Foundation | M6: =IF($B6="","",IFERROR(INDEX('Code Mapping'!$E$5:$E$1753,MATCH($B6,'Code Mapping'!$A$5:$A$1753,0)),"Unmapped")) -> Corporate discount | N6: =IF($F6="","",$F6) -> Urban Arena
A7: 8077 | B7: BRNA | C7: QIB 15% Discount | E7: 133 | F7: Urban Arena | G7: 2026-W37 | H7: 2 | I7: 11 | J7: 11 | K7: 106.5 | L7: =IF($B7="","",IFERROR(INDEX('Code Mapping'!$D$5:$D$1753,MATCH($B7,'Code Mapping'!$A$5:$A$1753,0)),"Unmapped")) -> QIB | M7: =IF($B7="","",IFERROR(INDEX('Code Mapping'!$E$5:$E$1753,MATCH($B7,'Code Mapping'!$A$5:$A$1753,0)),"Unmapped")) -> Corporate discount | N7: =IF($F7="","",$F7) -> Urban Arena
A8: 8038 | B8: cafe50 | C8: 50% off on cafe | E8: 133 | F8: Urban Arena | G8: 2026-W37 | H8: 31 | I8: 36 | J8: 36 | K8: 247.5 | L8: =IF($B8="","",IFERROR(INDEX('Code Mapping'!$D$5:$D$1753,MATCH($B8,'Code Mapping'!$A$5:$A$1753,0)),"Unmapped")) -> Internal / promotion | M8: =IF($B8="","",IFERROR(INDEX('Code Mapping'!$E$5:$E$1753,MATCH($B8,'Code Mapping'!$A$5:$A$1753,0)),"Unmapped")) -> Internal / promotion | N8: =IF($F8="","",$F8) -> Urban Arena
A9: 8095 | B9: CBOGOE | C9: Entertainer BOGO | E9: 61 | F9: Crayons & Bricks Vendome | G9: 2026-W37 | H9: 9 | I9: 9 | J9: 9 | K9: 900 | L9: =IF($B9="","",IFERROR(INDEX('Code Mapping'!$D$5:$D$1753,MATCH($B9,'Code Mapping'!$A$5:$A$1753,0)),"Unmapped")) -> Entertainer | M9: =IF($B9="","",IFERROR(INDEX('Code Mapping'!$E$5:$E$1753,MATCH($B9,'Code Mapping'!$A$5:$A$1753,0)),"Unmapped")) -> Aggregator BOGO | N9: =IF($F9="","",$F9) -> Crayons & Bricks Vendome
A10: 8097 | B10: CGBOGU | C10: Urban Point BOGO | E10: 61 | F10: Crayons & Bricks Vendome | G10: 2026-W37 | H10: 12 | I10: 12 | J10: 12 | K10: 1200 | L10: =IF($B10="","",IFERROR(INDEX('Code Mapping'!$D$5:$D$1753,MATCH($B10,'Code Mapping'!$A$5:$A$1753,0)),"Unmapped")) -> Urban Point | M10: =IF($B10="","",IFERROR(INDEX('Code Mapping'!$E$5:$E$1753,MATCH($B10,'Code Mapping'!$A$5:$A$1753,0)),"Unmapped")) -> Aggregator BOGO | N10: =IF($F10="","",$F10) -> Crayons & Bricks Vendome
A11: 8318 | B11: dmqnb15 | D11: QNB | E11: 133 | F11: Urban Arena | G11: 2026-W37 | H11: 3 | I11: 10 | J11: 10 | K11: 93 | L11: =IF($B11="","",IFERROR(INDEX('Code Mapping'!$D$5:$D$1753,MATCH($B11,'Code Mapping'!$A$5:$A$1753,0)),"Unmapped")) -> QNB Rewards | M11: =IF($B11="","",IFERROR(INDEX('Code Mapping'!$E$5:$E$1753,MATCH($B11,'Code Mapping'!$A$5:$A$1753,0)),"Unmapped")) -> Corporate discount | N11: =IF($F11="","",$F11) -> Urban Arena
A12: 8047 | B12: INFASPID | C12: Aspire 15% Discount | E12: 91 | F12: InflataPark | G12: 2026-W37 | H12: 1 | I12: 2 | J12: 2 | K12: 15 | L12: =IF($B12="","",IFERROR(INDEX('Code Mapping'!$D$5:$D$1753,MATCH($B12,'Code Mapping'!$A$5:$A$1753,0)),"Unmapped")) -> Aspire | M12: =IF($B12="","",IFERROR(INDEX('Code Mapping'!$E$5:$E$1753,MATCH($B12,'Code Mapping'!$A$5:$A$1753,0)),"Unmapped")) -> Corporate discount | N12: =IF($F12="","",$F12) -> InflataPark
A13: 8324 | B13: INFENTBOGO2 | D13: E3 | E13: 91 | F13: InflataPark | G13: 2026-W37 | H13: 4 | I13: 4 | J13: 4 | K13: 796 | L13: =IF($B13="","",IFERROR(INDEX('Code Mapping'!$D$5:$D$1753,MATCH($B13,'Code Mapping'!$A$5:$A$1753,0)),"Unmapped")) -> Entertainer | M13: =IF($B13="","",IFERROR(INDEX('Code Mapping'!$E$5:$E$1753,MATCH($B13,'Code Mapping'!$A$5:$A$1753,0)),"Unmapped")) -> Aggregator BOGO | N13: =IF($F13="","",$F13) -> InflataPark
A14: 8052 | B14: INFIMTYD | C14: Imtyazat 15% Discount | D14: E3 | E14: 91 | F14: InflataPark | G14: 2026-W37 | H14: 13 | I14: 55 | J14: 55 | K14: 465.75 | L14: =IF($B14="","",IFERROR(INDEX('Code Mapping'!$D$5:$D$1753,MATCH($B14,'Code Mapping'!$A$5:$A$1753,0)),"Unmapped")) -> Imtyazat | M14: =IF($B14="","",IFERROR(INDEX('Code Mapping'!$E$5:$E$1753,MATCH($B14,'Code Mapping'!$A$5:$A$1753,0)),"Unmapped")) -> Corporate discount | N14: =IF($F14="","",$F14) -> InflataPark
A15: 8053 | B15: INFPHSED | C15: Public Health Sector Employees 20% Discount | E15: 91 | F15: InflataPark | G15: 2026-W37 | H15: 13 | I15: 33 | J15: 33 | K15: 315 | L15: =IF($B15="","",IFERROR(INDEX('Code Mapping'!$D$5:$D$1753,MATCH($B15,'Code Mapping'!$A$5:$A$1753,0)),"Unmapped")) -> Public Health Sector (Sogha) | M15: =IF($B15="","",IFERROR(INDEX('Code Mapping'!$E$5:$E$1753,MATCH($B15,'Code Mapping'!$A$5:$A$1753,0)),"Unmapped")) -> Corporate discount | N15: =IF($F15="","",$F15) -> InflataPark
